<?xml version="1.0" ?>
<!-- =================================================================================== -->
<!-- |    This document was autogenerated by xacro from /home/sprinkle/ros15/trunk/gazebo_workspace/src/azcar_sim/urdf/azcar.xacro | -->
<!-- |    EDITING THIS FILE BY HAND IS NOT RECOMMENDED                                 | -->
<!-- =================================================================================== -->
<!--

Author: Jonathan Sprinkle, Sam Taylor, Alex Warren
Copyright (c) 2013-2016 Arizona Board of Regents
All rights reserved.

Permission is hereby granted, without written agreement and without 
license or royalty fees, to use, copy, modify, and distribute this
software and its documentation for any purpose, provided that the 
above copyright notice and the following two paragraphs appear in 
all copies of this software.

IN NO EVENT SHALL THE ARIZONA BOARD OF REGENTS BE LIABLE TO ANY PARTY 
FOR DIRECT, INDIRECT, SPECIAL, INCIDENTAL, OR CONSEQUENTIAL DAMAGES 
ARISING OUT OF THE USE OF THIS SOFTWARE AND ITS DOCUMENTATION, EVEN 
IF THE ARIZONA BOARD OF REGENTS HAS BEEN ADVISED OF THE POSSIBILITY OF 
SUCH DAMAGE.

THE ARIZONA BOARD OF REGENTS SPECIFICALLY DISCLAIMS ANY WARRANTIES, 
INCLUDING, BUT NOT LIMITED TO, THE IMPLIED WARRANTIES OF MERCHANTABILITY 
AND FITNESS FOR A PARTICULAR PURPOSE. THE SOFTWARE PROVIDED HEREUNDER
IS ON AN "AS IS" BASIS, AND THE ARIZONA BOARD OF REGENTS HAS NO OBLIGATION
TO PROVIDE MAINTENANCE, SUPPORT, UPDATES, ENHANCEMENTS, OR MODIFICATIONS.

Summary: 
=======
This launch file loads the worlds and models for the azcar

How to execute it:
=================
roslaunch azcar_sim azcar_empty.launch

-->
<!-- Inertial parameters selected with the help of 
http://www.car-engineer.com/vehicle-inertia-calculation-tool/
-->
<robot name="azcar_sim" xmlns:xacro="http://www.ros.org/wiki/xacro">
  <!--  <xacro:property name="base_height" value="0"/> -->
  <gazebo reference="back_right_wheel_link">
    <mu1>10000</mu1>
    <mu2>10000</mu2>
    <kp>10000000</kp>
    <kd>1</kd>
    <minDepth>0.01</minDepth>
    <maxVel>10.0</maxVel>
  </gazebo>
  <gazebo reference="back_left_wheel_link">
    <mu1>10000</mu1>
    <mu2>10000</mu2>
    <kp>10000000</kp>
    <kd>1</kd>
    <minDepth>0.01</minDepth>
    <maxVel>10.0</maxVel>
  </gazebo>
  <gazebo reference="front_right_wheel_link">
    <mu1>10000</mu1>
    <mu2>10000</mu2>
    <kp>1000000</kp>
    <kd>1</kd>
    <minDepth>0.01</minDepth>
    <maxVel>100.0</maxVel>
  </gazebo>
  <gazebo reference="front_left_wheel_link">
    <mu1>10000</mu1>
    <mu2>10000</mu2>
    <kp>1000000</kp>
    <kd>1</kd>
    <minDepth>0.01</minDepth>
    <maxVel>100.0</maxVel>
  </gazebo>
  <gazebo reference="front_right_steering_link">
    <mu1>0.6</mu1>
    <mu2>0.5</mu2>
    <kp>1000000</kp>
    <kd>0.1</kd>
    <minDepth>0.01</minDepth>
    <maxVel>10.0</maxVel>
  </gazebo>
  <gazebo reference="front_left_steering_link">
    <mu1>0.6</mu1>
    <mu2>0.5</mu2>
    <kp>1000000</kp>
    <kd>0.1</kd>
    <minDepth>0.01</minDepth>
    <maxVel>10.0</maxVel>
  </gazebo>
  <!--camera-->
  <!-- JMS removed to see if it improves sim times -->
  <!--
<gazebo reference="camera_link">
   <mu1>0.6</mu1>
   <mu2>0.5</mu2>
</gazebo>

<gazebo reference="camera_link">
   <sensor type="camera" name="camera1">
      <update_rate>30.0</update_rate>
      <camera name="head">
        <horizontal_fov>1.3962634</horizontal_fov>
        <image>
          <width>800</width>
          <height>800</height>
          <format>R8G8B8</format>
        </image>
        <clip>
          <near>0.02</near>
          <far>300</far>
        </clip>
        <noise>
          <type>gaussian</type>
           <mean>0.0</mean>
          <stddev>0.007</stddev>
        </noise>
      </camera>
      <plugin name="camera_controller" filename="libgazebo_ros_camera.so">
        <alwaysOn>true</alwaysOn>
        <updateRate>0.0</updateRate>
    	<robotNamespace>/$(arg roboname)</robotNamespace>
        <cameraName>camera1</cameraName>
        <imageTopicName>image_raw</imageTopicName>
        <cameraInfoTopicName>camera_info</cameraInfoTopicName>
        <frameName>camera_link</frameName>
        <hackBaseline>0.07</hackBaseline>
        <distortionK1>0.0</distortionK1>
        <distortionK2>0.0</distortionK2>
        <distortionK3>0.0</distortionK3>
        <distortionT1>0.0</distortionT1>
        <distortionT2>0.0</distortionT2>
      </plugin>
    </sensor>
</gazebo>
-->
  <gazebo reference="laser_link">
    <mu1>0.6</mu1>
    <mu2>0.5</mu2>
  </gazebo>
  <gazebo reference="laser_link">
    <sensor name="lidar_sensor" type="ray">
      <pose>0 0 0 0 0 0</pose>
      <visualize>false</visualize>
      <update_rate>5</update_rate>
      <ray>
        <scan>
          <horizontal>
            <samples>100</samples>
            <resolution>1</resolution>
            <min_angle>-0.4</min_angle>
            <max_angle>0.4</max_angle>
          </horizontal>
          <vertical>
            <samples>20</samples>
            <resolution>1</resolution>
            <min_angle>-0.034906585</min_angle>
            <!--			<max_angle>0.432841654</max_angle> -->
            <max_angle>0.326</max_angle>
          </vertical>
        </scan>
        <range>
          <min>1</min>
          <max>50.0</max>
          <resolution>0.02</resolution>
        </range>
      </ray>
      <!--                <plugin name="gazebo_ros_head_hokuyo_controller" filename="libgazebo_ros_laser.so">
                   <topicName>/cat/laser/scan</topicName>
                      <frameName>laser_link</frameName>  -->
      <plugin filename="libgazebo_ros_block_laser.so" name="laser_controller">
        <frameName>laser_link</frameName>
        <hokuyoMinIntensity>101</hokuyoMinIntensity>
        <robotNamespace>/azcar_sim</robotNamespace>
        <topicName>lidar_points</topicName>
        <gaussianNoise>0.02</gaussianNoise>
        <updateRate>5</updateRate>
      </plugin>
    </sensor>
  </gazebo>
  <gazebo reference="front_laser_link">
    <mu1>0.6</mu1>
    <mu2>0.5</mu2>
  </gazebo>
  <gazebo reference="front_laser_link">
    <sensor name="sick_lms291" type="ray">
      <pose>0 0 0 0 0 0</pose>
      <visualize>true</visualize>
      <update_rate>50</update_rate>
      <ray>
        <scan>
          <horizontal>
            <samples>180</samples>
            <resolution>1</resolution>
            <min_angle>-1.57</min_angle>
            <max_angle>1.57</max_angle>
          </horizontal>
        </scan>
        <range>
          <min>1.5</min>
          <!-- This range is in m, I hope... -->
          <max>80.0</max>
          <resolution>0.05</resolution>
        </range>
        <!--
                           <noise>
                                <type>gaussian</type>
                                <mean>0.0</mean>
                                <stddev>0.02</stddev>
                           </noise>
-->
      </ray>
      <plugin filename="libgazebo_ros_laser.so" name="sick_lms291_controller">
        <!--			      <robotNamespace>/azcar_sim</robotNamespace>-->
        <topicName>/azcar_sim/front_laser_points</topicName>
        <frameName>front_laser_link</frameName>
        <gaussianNoise>0.02</gaussianNoise>
      </plugin>
    </sensor>
  </gazebo>
  <gazebo>
    <plugin filename="libgazebo_ros_control.so" name="gazebo_ros_control">
      <robotNamespace>/azcar_sim</robotNamespace>
      <robotSimType>gazebo_ros_control/DefaultRobotHWSim</robotSimType>
    </plugin>
  </gazebo>
  <!--Rear Wheel Drive, cuz why not-->
  <!--
<gazebo>
  <plugin name="differential_drive_controller" filename="libgazebo_ros_diff_drive.so">
      <robotNamespace>/azcar_sim</robotNamespace>
      <rosDebugLevel>Debug</rosDebugLevel>
      <publishWheelTF>false</publishWheelTF>
      <publishWheelJointState>true</publishWheelJointState>
      <alwaysOn>true</alwaysOn>
      <leftJoint>back_left_wheel_joint</leftJoint>
      <rightJoint>back_right_wheel_joint</rightJoint>
      <wheelSeparation>1.73</wheelSeparation>
      <wheelDiameter>0.712</wheelDiameter>
      <wheelTorque>350</wheelTorque>
      <wheelAcceleration>1.0</wheelAcceleration>
      <commandTopic>cmd_vel</commandTopic>
      <odometryTopic>odom</odometryTopic>
      <odometryFrame>odom</odometryFrame>
      <odometrySource>world</odometrySource>
      <robotBaseFrame>base_link</robotBaseFrame>
      <cmd_vel_timeout>0.20</cmd_vel_timeout>
      <updateRate>10.0</updateRate>
  </plugin>
</gazebo>
-->
  <gazebo>
    <plugin filename="libgazebo_ros_joint_state_publisher.so" name="joint_state_publisher">
      <jointName>back_left_wheel_joint, back_right_wheel_joint, front_left_steering_joint, front_right_steering_joint, front_right_wheel_joint, front_left_wheel_joint</jointName>
      <updateRate>50.0</updateRate>
      <robotNamespace>/azcar_sim</robotNamespace>
      <alwaysOn>true</alwaysOn>
    </plugin>
  </gazebo>
  <gazebo>
    <plugin filename="libazcargazebo.so" name="cmdvel_controller">
      <robotNamespace>/azcar_sim</robotNamespace>
    </plugin>
  </gazebo>
  <!--Car Body-->
  <link name="base_link">
    <collision>
      <origin rpy="0 0 0" xyz="0 0 1.0639"/>
      <geometry>
        <box size="2.62 1.301 1.4478"/>
      </geometry>
    </collision>
    <visual>
      <origin rpy="0 0 0" xyz="-0.25 0 1.1139"/>
      <geometry>
        <mesh filename="package://azcar_sim/meshes/ford_escape_no_wheels_2.dae"/>
      </geometry>
    </visual>
  </link>
  <joint name="inertial_joint" type="fixed">
    <parent link="base_link"/>
    <child link="main_mass"/>
    <origin rpy="0 0 0" xyz="0 0 0"/>
  </joint>
  <link name="main_mass" type="fixed">
    <parent link="inertial_joint"/>
    <inertial>
      <origin rpy="0 0 0" xyz="0 0 1.0639"/>
      <mass value="2050"/>
      <inertia ixx="63" ixy="0.000000" ixz="-31" iyy="1048" iyz="0.000000" izz="1111"/>
    </inertial>
  </link>
  <!--Back Right Wheel-->
  <joint name="back_right_wheel_joint" type="continuous">
    <parent link="base_link"/>
    <child link="back_right_wheel_link"/>
    <origin rpy="0 0 0" xyz="-1.31 -0.765 0.66"/>
    <axis xyz="0 1 0"/>
    <dynamics damping="0.1"/>
    <limit effort="10000" velocity="100"/>
    <joint_properties damping="0.0" friction="0.0"/>
  </joint>
  <link name="back_right_wheel_link">
    <collision>
      <origin rpy="1.57079634179 0 0" xyz="0 0 0"/>
      <geometry>
        <cylinder length="0.229" radius="0.356"/>
      </geometry>
    </collision>
    <visual>
      <origin rpy="0 0 -1.57079634179" xyz="0 0 0"/>
      <geometry>
        <mesh filename="package://azcar_sim/meshes/ford_escape_wheel.dae"/>
        <scale xyz="1.2 1 1"/>
      </geometry>
    </visual>
    <inertial>
      <origin rpy="0 0 0" xyz="0 0 0"/>
      <mass value="40"/>
      <inertia ixx="54" ixy="0.000000" ixz="0.000000" iyy="56" iyz="0.000000" izz="104"/>
    </inertial>
  </link>
  <!--Back Left Wheel-->
  <joint name="back_left_wheel_joint" type="continuous">
    <parent link="base_link"/>
    <child link="back_left_wheel_link"/>
    <origin rpy="0 0 0" xyz="-1.31 0.765 0.66"/>
    <axis xyz="0 1 0"/>
    <dynamics damping="0.1"/>
    <limit effort="10000" velocity="100"/>
    <joint_properties damping="0.0" friction="0.0"/>
  </joint>
  <link name="back_left_wheel_link">
    <collision>
      <origin rpy="1.57079634179 0 0" xyz="0 0 0"/>
      <geometry>
        <cylinder length="0.229" radius="0.356"/>
      </geometry>
    </collision>
    <visual>
      <origin rpy="0 0 1.57079634179" xyz="0 0 0"/>
      <geometry>
        <mesh filename="package://azcar_sim/meshes/ford_escape_wheel.dae"/>
        <scale xyz="1.2 1 1"/>
      </geometry>
    </visual>
    <inertial>
      <origin rpy="0 0 0" xyz="0 0 0"/>
      <mass value="40"/>
      <inertia ixx="54" ixy="0.000000" ixz="0.000000" iyy="56" iyz="0.000000" izz="104"/>
    </inertial>
  </link>
  <!--Right Steering-->
  <joint name="front_right_steering_joint" type="revolute">
    <parent link="base_link"/>
    <child link="front_right_steering_link"/>
    <origin rpy="0 0 0" xyz="1.31 -0.6555 0.66"/>
    <axis xyz="0 0 1"/>
    <limit effort="1000.0" lower="-0.6" upper="0.6" velocity="0.5"/>
  </joint>
  <link name="front_right_steering_link">
    <collision>
      <origin rpy="1.57079634179 0 0" xyz="0 0 0"/>
      <geometry>
        <cylinder length="0.01" radius="0.1"/>
      </geometry>
    </collision>
    <visual>
      <origin rpy="1.57079634179 0 0" xyz="0 0 0"/>
      <geometry>
        <cylinder length="0.01" radius="0.1"/>
      </geometry>
    </visual>
    <inertial>
      <origin rpy="0 0 0" xyz="0 0 0"/>
      <mass value="10.00"/>
      <inertia ixx="0.4" ixy="0.000000" ixz="0.000000" iyy="0.6" iyz="0.000000" izz="0.4"/>
    </inertial>
  </link>
  <!--Right Front Wheel-->
  <joint name="front_right_wheel_joint" type="continuous">
    <parent link="front_right_steering_link"/>
    <child link="front_right_wheel_link"/>
    <origin rpy="0 0 0" xyz="0 -0.1195 0"/>
    <axis xyz="0 1 0"/>
  </joint>
  <link name="front_right_wheel_link">
    <collision>
      <origin rpy="1.57079634179 0 0" xyz="0 0 0"/>
      <geometry>
        <cylinder length="0.229" radius="0.356"/>
      </geometry>
    </collision>
    <visual>
      <origin rpy="0 0 -1.57079634179" xyz="0 0 0"/>
      <geometry>
        <mesh filename="package://azcar_sim/meshes/ford_escape_wheel.dae"/>
        <scale xyz="1.2 1 1"/>
      </geometry>
    </visual>
    <inertial>
      <origin rpy="0 0 0" xyz="0 0 0"/>
      <mass value="40"/>
      <inertia ixx="54" ixy="0.000000" ixz="0.000000" iyy="56" iyz="0.000000" izz="104"/>
    </inertial>
  </link>
  <!--Left Steering-->
  <joint name="front_left_steering_joint" type="revolute">
    <parent link="base_link"/>
    <child link="front_left_steering_link"/>
    <origin rpy="0 0 0" xyz="1.31 0.6555 0.66"/>
    <axis xyz="0 0 1"/>
    <limit effort="1000.0" lower="-0.6" upper="0.6" velocity="0.5"/>
  </joint>
  <link name="front_left_steering_link">
    <parent link="base_link"/>
    <collision>
      <origin rpy="1.57079634179 0 0" xyz="0 0 0"/>
      <geometry>
        <cylinder length="0.01" radius="0.1"/>
      </geometry>
    </collision>
    <visual>
      <origin rpy="1.57079634179 0 0" xyz="0 0 0"/>
      <geometry>
        <cylinder length="0.01" radius="0.1"/>
      </geometry>
    </visual>
    <inertial>
      <origin rpy="0 0 0" xyz="0 0 0"/>
      <mass value="10.00"/>
      <inertia ixx="0.4" ixy="0.000000" ixz="0.000000" iyy="0.6" iyz="0.000000" izz="0.4"/>
    </inertial>
  </link>
  <!--Front Right Wheel-->
  <joint name="front_left_wheel_joint" type="continuous">
    <parent link="front_left_steering_link"/>
    <child link="front_left_wheel_link"/>
    <origin rpy="0 0 0" xyz="0 0.1195 0"/>
    <axis xyz="0 1 0"/>
    <dynamics damping="0.1"/>
    <limit effort="10000" velocity="100"/>
    <joint_properties damping="0.0" friction="0.0"/>
  </joint>
  <link name="front_left_wheel_link">
    <parent link="front_left_wheel_joint"/>
    <collision>
      <origin rpy="1.57079634179 0 0" xyz="0 0 0"/>
      <geometry>
        <cylinder length="0.229" radius="0.356"/>
      </geometry>
    </collision>
    <visual>
      <origin rpy="0 0 1.57079634179" xyz="0 0 0"/>
      <geometry>
        <mesh filename="package://azcar_sim/meshes/ford_escape_wheel.dae"/>
        <scale xyz="1.2 1 1"/>
      </geometry>
    </visual>
    <inertial>
      <origin rpy="0 0 0" xyz="0 0 0"/>
      <mass value="40"/>
      <inertia ixx="54" ixy="0.000000" ixz="0.000000" iyy="56" iyz="0.000000" izz="104"/>
    </inertial>
  </link>
  <!-- Camera-->
  <joint name="camera_joint" type="fixed">
    <origin rpy="0 0 0" xyz="0 0 2.1"/>
    <axis xyz="0 0 1"/>
    <parent link="base_link"/>
    <child link="camera_link"/>
  </joint>
  <link name="camera_link">
    <collision>
      <origin rpy="0 0 0" xyz="0 0 0"/>
      <geometry>
        <box size="0.25 0.25 0.25"/>
      </geometry>
    </collision>
    <visual>
      <origin rpy="0 0 0" xyz="0 0 0"/>
      <geometry>
        <box size="0.25 0.25 0.25"/>
      </geometry>
    </visual>
    <inertial>
      <mass value="1e-5"/>
      <origin rpy="0 0 0" xyz="0 0 0"/>
      <inertia ixx="1e-6" ixy="0" ixz="0" iyy="1e-6" iyz="0" izz="1e-6"/>
    </inertial>
  </link>
  <!--Velodyne LIDAR-->
  <joint name="laser_joint" type="fixed">
    <origin rpy="0 0 0" xyz="0 0 0.135"/>
    <axis xyz="0 0 1"/>
    <parent link="camera_link"/>
    <child link="laser_link"/>
  </joint>
  <link name="laser_link">
    <collision>
      <origin rpy="0 0 0" xyz="0 0 0"/>
      <geometry>
        <box size="0.25 0.25 0.25"/>
      </geometry>
    </collision>
    <visual>
      <origin rpy="0 0 0" xyz="0 0 0"/>
      <geometry>
        <mesh filename="package://azcar_sim/meshes/hokuyo.dae"/>
      </geometry>
    </visual>
    <inertial>
      <mass value="1e-5"/>
      <origin rpy="0 0 0" xyz="0 0 0"/>
      <inertia ixx="1e-6" ixy="0" ixz="0" iyy="1e-6" iyz="0" izz="1e-6"/>
    </inertial>
  </link>
  <joint name="front_laser_joint" type="fixed">
    <origin rpy="0 0 0" xyz="2.4 0 0.8589"/>
    <axis xyz="0 0 1"/>
    <parent link="base_link"/>
    <child link="front_laser_link"/>
  </joint>
  <link name="front_laser_link">
    <parent link="front_laser_joint"/>
    <collision>
      <origin rpy="0 0.0 0" xyz="0 0 0"/>
      <geometry>
        <box size="0.25 0.25 0.25"/>
      </geometry>
    </collision>
    <visual>
      <origin rpy="0 0 0" xyz="0 0 0"/>
      <geometry>
        <box size="0.25 0.25 0.25"/>
      </geometry>
    </visual>
    <inertial>
      <mass value="1e-5"/>
      <origin rpy="0 0 0" xyz="0 0 0"/>
      <inertia ixx="1e-6" ixy="0" ixz="0" iyy="1e-6" iyz="0" izz="1e-6"/>
    </inertial>
  </link>
  <!-- motors and transmissions for the two rear wheels -->
  <transmission name="tran1">
    <type>transmission_interface/SimpleTransmission</type>
    <joint name="back_right_wheel_joint">
      <hardwareInterface>VelocityJointInterface</hardwareInterface>
    </joint>
    <actuator name="motor1">
      <hardwareInterface>VelocityJointInterface</hardwareInterface>
      <mechanicalReduction>1</mechanicalReduction>
    </actuator>
  </transmission>
  <transmission name="tran2">
    <type>transmission_interface/SimpleTransmission</type>
    <joint name="back_left_wheel_joint">
      <hardwareInterface>VelocityJointInterface</hardwareInterface>
    </joint>
    <actuator name="motor2">
      <hardwareInterface>VelocityJointInterface</hardwareInterface>
      <mechanicalReduction>1</mechanicalReduction>
    </actuator>
  </transmission>
  <transmission name="rack_and_pinion_left">
    <type>transmission_interface/SimpleTransmission</type>
    <joint name="front_left_steering_joint">
      <hardwareInterface>PositionJointInterface</hardwareInterface>
    </joint>
    <actuator name="eps_left">
      <hardwareInterface>PositionJointInterface</hardwareInterface>
      <mechanicalReduction>1</mechanicalReduction>
    </actuator>
  </transmission>
  <transmission name="rack_and_pinion_right">
    <type>transmission_interface/SimpleTransmission</type>
    <joint name="front_right_steering_joint">
      <hardwareInterface>PositionJointInterface</hardwareInterface>
    </joint>
    <actuator name="eps_right">
      <hardwareInterface>PositionJointInterface</hardwareInterface>
      <mechanicalReduction>1</mechanicalReduction>
    </actuator>
  </transmission>
</robot>
